Workbook

Sheet Instructions
A1: Instructions for use:
A2: 1. Determine the Estuary and Stations for which the data needs to be added. Confirm the stations are present in the FixedLocations Table.
A3: 2. Enter the four-letter data type (i.e. RCRT), the 2-letter estuary code, and the station number for the data in ColA-C.
A4: 3. Fill in the date and data columns as able. If no data is recorded, leave the cell blank. RecordNumber = per event record (i.e. "1" in most cases)
A5: 4. Enter your name and the date in the EnteredBy and DateEntered columns.
A6: 5. On the "Template" sheet, use the formulas in row 2 to fill down until all stations are represented. Make sure to fill formulas in all columns (A:X)
A8: DataType | B8: Date | C8: Estuary | D8: SectionName | E8: StationNumber | F8: SampleNumber | G8: Sex | H8: ReproStage | I8: Parasite | J8: BadSlide | K8: DataStatus | L8: DateEntered | M8: EnteredBy | N8: DateProofed | O8: ProofedBy | P8: Comments | Q8: AdminNotes
A9: COLL | B9: 45903 | C9: LX | D9: N | E9: 1 | F9: 16 | G9: F | H9: 2 | I9: No | J9: N | K9: Proofed | L9: 45957 | M9: Lily Harmon | N9: 45957 | O9: Lily Harmon | Q9: Added via SMSS
A10: COLL | B10: 45903 | C10: LX | D10: N | E10: 1 | F10: 17 | G10: F | H10: 2 | I10: No | J10: N | K10: Proofed | L10: 45957 | M10: Lily Harmon | N10: 45957 | O10: Lily Harmon | Q10: Added via SMSS
A11: COLL | B11: 45903 | C11: LX | D11: N | E11: 1 | F11: 18 | G11: Z | H11: 4 | I11: No | J11: N | K11: Proofed | L11: 45957 | M11: Lily Harmon | N11: 45957 | O11: Lily Harmon | P11: 1=mat | Q11: Added via SMSS
A12: COLL | B12: 45903 | C12: LX | D12: N | E12: 1 | F12: 19 | G12: M | H12: 2 | I12: No | J12: N | K12: Proofed | L12: 45957 | M12: Lily Harmon | N12: 45957 | O12: Lily Harmon | Q12: Added via SMSS
A13: COLL | B13: 45903 | C13: LX | D13: N | E13: 1 | F13: 20 | G13: F | H13: 2 | I13: No | J13: N | K13: Proofed | L13: 45957 | M13: Lily Harmon | N13: 45957 | O13: Lily Harmon | Q13: Added via SMSS
A14: COLL | B14: 45903 | C14: LX | D14: N | E14: 1 | F14: 21 | G14: F | H14: 2 | I14: No | J14: N | K14: Proofed | L14: 45957 | M14: Lily Harmon | N14: 45957 | O14: Lily Harmon | Q14: Added via SMSS
A15: COLL | B15: 45903 | C15: LX | D15: N | E15: 1 | F15: 22 | G15: M | H15: 2 | I15: No | J15: N | K15: Proofed | L15: 45957 | M15: Lily Harmon | N15: 45957 | O15: Lily Harmon | Q15: Added via SMSS
A16: COLL | B16: 45903 | C16: LX | D16: N | E16: 1 | F16: 23 | G16: Z | H16: Z | I16: No | J16: Y | K16: Proofed | L16: 45957 | M16: Lily Harmon | N16: 45957 | O16: Lily Harmon | Q16: Added via SMSS
A17: COLL | B17: 45903 | C17: LX | D17: N | E17: 1 | F17: 24 | G17: M | H17: 2 | I17: No | J17: N | K17: Proofed | L17: 45957 | M17: Lily Harmon | N17: 45957 | O17: Lily Harmon | Q17: Added via SMSS
A18: COLL | B18: 45903 | C18: LX | D18: N | E18: 1 | F18: 25 | G18: Z | H18: Z | I18: No | J18: N | K18: Proofed | L18: 45957 | M18: Lily Harmon | N18: 45957 | O18: Lily Harmon | P18: Missing slide | Q18: Added via SMSS
A19: COLL | B19: 45903 | C19: LX | D19: N | E19: 2 | F19: 26 | G19: M | H19: 2 | I19: No | J19: N | K19: Proofed | L19: 45957 | M19: Lily Harmon | N19: 45957 | O19: Lily Harmon | Q19: Added via SMSS
A20: COLL | B20: 45903 | C20: LX | D20: N | E20: 2 | F20: 27 | G20: M | H20: 2 | I20: No | J20: N | K20: Proofed | L20: 45957 | M20: Lily Harmon | N20: 45957 | O20: Lily Harmon | Q20: Added via SMSS
A21: COLL | B21: 45903 | C21: LX | D21: N | E21: 2 | F21: 28 | G21: F | H21: 2 | I21: No | J21: N | K21: Proofed | L21: 45957 | M21: Lily Harmon | N21: 45957 | O21: Lily Harmon | Q21: Added via SMSS
A22: COLL | B22: 45903 | C22: LX | D22: N | E22: 2 | F22: 29 | G22: M | H22: 3 | I22: No | J22: N | K22: Proofed | L22: 45957 | M22: Lily Harmon | N22: 45957 | O22: Lily Harmon | Q22: Added via SMSS
A23: COLL | B23: 45903 | C23: LX | D23: N | E23: 2 | F23: 30 | G23: M | H23: 2 | I23: No | J23: N | K23: Proofed | L23: 45957 | M23: Lily Harmon | N23: 45957 | O23: Lily Harmon | Q23: Added via SMSS
A24: COLL | B24: 45903 | C24: LX | D24: N | E24: 2 | F24: 31 | G24: M | H24: 2 | I24: No | J24: N | K24: Proofed | L24: 45957 | M24: Lily Harmon | N24: 45957 | O24: Lily Harmon | Q24: Added via SMSS
A25: COLL | B25: 45903 | C25: LX | D25: N | E25: 2 | F25: 32 | G25: M | H25: 1 | I25: No | J25: N | K25: Proofed | L25: 45957 | M25: Lily Harmon | N25: 45957 | O25: Lily Harmon | Q25: Added via SMSS
A26: COLL | B26: 45903 | C26: LX | D26: N | E26: 2 | F26: 33 | G26: F | H26: 2 | I26: No | J26: N | K26: Proofed | L26: 45957 | M26: Lily Harmon | N26: 45957 | O26: Lily Harmon | Q26: Added via SMSS
A27: COLL | B27: 45903 | C27: LX | D27: N | E27: 2 | F27: 34 | G27: M | H27: 2 | I27: No | J27: N | K27: Proofed | L27: 45957 | M27: Lily Harmon | N27: 45957 | O27: Lily Harmon | Q27: Added via SMSS
A28: COLL | B28: 45903 | C28: LX | D28: N | E28: 2 | F28: 35 | G28: Z | H28: 4 | I28: No | J28: N | K28: Proofed | L28: 45957 | M28: Lily Harmon | N28: 45957 | O28: Lily Harmon | P28: 1=mat | Q28: Added via SMSS
A29: COLL | B29: 45903 | C29: LX | D29: N | E29: 3 | F29: 36 | G29: F | H29: 2 | I29: No | J29: N | K29: Proofed | L29: 45957 | M29: Lily Harmon | N29: 45957 | O29: Lily Harmon | Q29: Added via SMSS
A30: COLL | B30: 45903 | C30: LX | D30: N | E30: 3 | F30: 37 | G30: F | H30: 2 | I30: No | J30: N | K30: Proofed | L30: 45957 | M30: Lily Harmon | N30: 45957 | O30: Lily Harmon | Q30: Added via SMSS
A31: COLL | B31: 45903 | C31: LX | D31: N | E31: 3 | F31: 38 | G31: M | H31: 2 | I31: No | J31: N | K31: Proofed | L31: 45957 | M31: Lily Harmon | N31: 45957 | O31: Lily Harmon | Q31: Added via SMSS
A32: COLL | B32: 45903 | C32: LX | D32: N | E32: 3 | F32: 39 | G32: M | H32: 2 | I32: No | J32: N | K32: Proofed | L32: 45957 | M32: Lily Harmon | N32: 45957 | O32: Lily Harmon | Q32: Added via SMSS
A33: COLL | B33: 45903 | C33: LX | D33: N | E33: 3 | F33: 40 | G33: M | H33: 2 | I33: Yes | J33: N | K33: Proofed | L33: 45957 | M33: Lily Harmon | N33: 45957 | O33: Lily Harmon | Q33: Added via SMSS
A34: COLL | B34: 45903 | C34: LX | D34: N | E34: 3 | F34: 41 | G34: M | H34: 2 | I34: No | J34: N | K34: Proofed | L34: 45957 | M34: Lily Harmon | N34: 45957 | O34: Lily Harmon | Q34: Added via SMSS
A35: COLL | B35: 45903 | C35: LX | D35: N | E35: 3 | F35: 42 | G35: M | H35: 2 | I35: No | J35: N | K35: Proofed | L35: 45957 | M35: Lily Harmon | N35: 45957 | O35: Lily Harmon | Q35: Added via SMSS
A36: COLL | B36: 45903 | C36: LX | D36: N | E36: 3 | F36: 43 | G36: M | H36: 3 | I36: No | J36: N | K36: Proofed | L36: 45957 | M36: Lily Harmon | N36: 45957 | O36: Lily Harmon | Q36: Added via SMSS
A37: COLL | B37: 45903 | C37: LX | D37: N | E37: 3 | F37: 44 | G37: Z | H37: 4 | I37: No | J37: N | K37: Proofed | L37: 45957 | M37: Lily Harmon | N37: 45957 | O37: Lily Harmon | P37: 0=imm | Q37: Added via SMSS
A38: COLL | B38: 45903 | C38: LX | D38: N | E38: 3 | F38: 45 | G38: Z | H38: 4 | I38: No | J38: N | K38: Proofed | L38: 45957 | M38: Lily Harmon | N38: 45957 | O38: Lily Harmon | P38: 0=imm | Q38: Added via SMSS

Sheet Template
A1: OysterID | B1: SampleEventID | C1: Sex | D1: ReproStage | E1: Parasite | F1: BadSlide | G1: DataStatus | H1: DateEntered | I1: EnteredBy | J1: DateProofed | K1: ProofedBy | L1: Comments | M1: AdminNotes
A2: =_xlfn.CONCAT(Instructions!C9,Instructions!D9,"D",TEXT(Instructions!B9,"YY"),TEXT(Instructions!B9,"MM"),"-",TEXT(Instructions!F9,"00")) -> LXND2509-16 | B2: {=_xlfn.CONCAT(Instructions!C9,Instructions!A9,"_",TEXT(Instructions!B9,"YYYYMMDD"),"_1_",INDEX(Table1[], MATCH(1,(Table1[Estuary]=Instructions!C9)*(Table1[SectionName]=Instructions!D9)*(Table1[StationNumber]=Instructions!E9)*(Instructions!B9>Table1[StartDate])*(Instructions!B9<Table1[EndDate]),0),1),"_1")} -> LXCOLL_20250903_1_0242_1 | C2: =Instructions!G9 -> F | D2: =Instructions!H9 -> 2 | E2: =Instructions!I9 -> No | F2: =Instructions!J9 -> N | G2: =Instructions!K9 -> Proofed | H2: =IF(ISBLANK(Instructions!L9),"",Instructions!L9) -> 45957 | I2: =IF(ISBLANK(Instructions!M9),"",Instructions!M9) -> Lily Harmon | J2: =IF(ISBLANK(Instructions!N9),"",Instructions!N9) -> 45957 | K2: =IF(ISBLANK(Instructions!O9),"",Instructions!O9) -> Lily Harmon | L2: =IF(ISBLANK(Instructions!P9),"",Instructions!P9) | M2: =Instructions!Q9 -> Added via SMSS
A3: =_xlfn.CONCAT(Instructions!C10,Instructions!D10,"D",TEXT(Instructions!B10,"YY"),TEXT(Instructions!B10,"MM"),"-",TEXT(Instructions!F10,"00")) -> LXND2509-17 | B3: {=_xlfn.CONCAT(Instructions!C10,Instructions!A10,"_",TEXT(Instructions!B10,"YYYYMMDD"),"_1_",INDEX(Table1[], MATCH(1,(Table1[Estuary]=Instructions!C10)*(Table1[SectionName]=Instructions!D10)*(Table1[StationNumber]=Instructions!E10)*(Instructions!B10>Table1[StartDate])*(Instructions!B10<Table1[EndDate]),0),1),"_1")} -> LXCOLL_20250903_1_0242_1 | C3: =Instructions!G10 -> F | D3: =Instructions!H10 -> 2 | E3: =Instructions!I10 -> No | F3: =Instructions!J10 -> N | G3: =Instructions!K10 -> Proofed | H3: =IF(ISBLANK(Instructions!L10),"",Instructions!L10) -> 45957 | I3: =IF(ISBLANK(Instructions!M10),"",Instructions!M10) -> Lily Harmon | J3: =IF(ISBLANK(Instructions!N10),"",Instructions!N10) -> 45957 | K3: =IF(ISBLANK(Instructions!O10),"",Instructions!O10) -> Lily Harmon | L3: =IF(ISBLANK(Instructions!P10),"",Instructions!P10) | M3: =Instructions!Q10 -> Added via SMSS
A4: =_xlfn.CONCAT(Instructions!C11,Instructions!D11,"D",TEXT(Instructions!B11,"YY"),TEXT(Instructions!B11,"MM"),"-",TEXT(Instructions!F11,"00")) -> LXND2509-18 | B4: {=_xlfn.CONCAT(Instructions!C11,Instructions!A11,"_",TEXT(Instructions!B11,"YYYYMMDD"),"_1_",INDEX(Table1[], MATCH(1,(Table1[Estuary]=Instructions!C11)*(Table1[SectionName]=Instructions!D11)*(Table1[StationNumber]=Instructions!E11)*(Instructions!B11>Table1[StartDate])*(Instructions!B11<Table1[EndDate]),0),1),"_1")} -> LXCOLL_20250903_1_0242_1 | C4: =Instructions!G11 -> Z | D4: =Instructions!H11 -> 4 | E4: =Instructions!I11 -> No | F4: =Instructions!J11 -> N | G4: =Instructions!K11 -> Proofed | H4: =IF(ISBLANK(Instructions!L11),"",Instructions!L11) -> 45957 | I4: =IF(ISBLANK(Instructions!M11),"",Instructions!M11) -> Lily Harmon | J4: =IF(ISBLANK(Instructions!N11),"",Instructions!N11) -> 45957 | K4: =IF(ISBLANK(Instructions!O11),"",Instructions!O11) -> Lily Harmon | L4: =IF(ISBLANK(Instructions!P11),"",Instructions!P11) -> 1=mat | M4: =Instructions!Q11 -> Added via SMSS
A5: =_xlfn.CONCAT(Instructions!C12,Instructions!D12,"D",TEXT(Instructions!B12,"YY"),TEXT(Instructions!B12,"MM"),"-",TEXT(Instructions!F12,"00")) -> LXND2509-19 | B5: {=_xlfn.CONCAT(Instructions!C12,Instructions!A12,"_",TEXT(Instructions!B12,"YYYYMMDD"),"_1_",INDEX(Table1[], MATCH(1,(Table1[Estuary]=Instructions!C12)*(Table1[SectionName]=Instructions!D12)*(Table1[StationNumber]=Instructions!E12)*(Instructions!B12>Table1[StartDate])*(Instructions!B12<Table1[EndDate]),0),1),"_1")} -> LXCOLL_20250903_1_0242_1 | C5: =Instructions!G12 -> M | D5: =Instructions!H12 -> 2 | E5: =Instructions!I12 -> No | F5: =Instructions!J12 -> N | G5: =Instructions!K12 -> Proofed | H5: =IF(ISBLANK(Instructions!L12),"",Instructions!L12) -> 45957 | I5: =IF(ISBLANK(Instructions!M12),"",Instructions!M12) -> Lily Harmon | J5: =IF(ISBLANK(Instructions!N12),"",Instructions!N12) -> 45957 | K5: =IF(ISBLANK(Instructions!O12),"",Instructions!O12) -> Lily Harmon | L5: =IF(ISBLANK(Instructions!P12),"",Instructions!P12) | M5: =Instructions!Q12 -> Added via SMSS
A6: =_xlfn.CONCAT(Instructions!C13,Instructions!D13,"D",TEXT(Instructions!B13,"YY"),TEXT(Instructions!B13,"MM"),"-",TEXT(Instructions!F13,"00")) -> LXND2509-20 | B6: {=_xlfn.CONCAT(Instructions!C13,Instructions!A13,"_",TEXT(Instructions!B13,"YYYYMMDD"),"_1_",INDEX(Table1[], MATCH(1,(Table1[Estuary]=Instructions!C13)*(Table1[SectionName]=Instructions!D13)*(Table1[StationNumber]=Instructions!E13)*(Instructions!B13>Table1[StartDate])*(Instructions!B13<Table1[EndDate]),0),1),"_1")} -> LXCOLL_20250903_1_0242_1 | C6: =Instructions!G13 -> F | D6: =Instructions!H13 -> 2 | E6: =Instructions!I13 -> No | F6: =Instructions!J13 -> N | G6: =Instructions!K13 -> Proofed | H6: =IF(ISBLANK(Instructions!L13),"",Instructions!L13) -> 45957 | I6: =IF(ISBLANK(Instructions!M13),"",Instructions!M13) -> Lily Harmon | J6: =IF(ISBLANK(Instructions!N13),"",Instructions!N13) -> 45957 | K6: =IF(ISBLANK(Instructions!O13),"",Instructions!O13) -> Lily Harmon | L6: =IF(ISBLANK(Instructions!P13),"",Instructions!P13) | M6: =Instructions!Q13 -> Added via SMSS
A7: =_xlfn.CONCAT(Instructions!C14,Instructions!D14,"D",TEXT(Instructions!B14,"YY"),TEXT(Instructions!B14,"MM"),"-",TEXT(Instructions!F14,"00")) -> LXND2509-21 | B7: {=_xlfn.CONCAT(Instructions!C14,Instructions!A14,"_",TEXT(Instructions!B14,"YYYYMMDD"),"_1_",INDEX(Table1[], MATCH(1,(Table1[Estuary]=Instructions!C14)*(Table1[SectionName]=Instructions!D14)*(Table1[StationNumber]=Instructions!E14)*(Instructions!B14>Table1[StartDate])*(Instructions!B14<Table1[EndDate]),0),1),"_1")} -> LXCOLL_20250903_1_0242_1 | C7: =Instructions!G14 -> F | D7: =Instructions!H14 -> 2 | E7: =Instructions!I14 -> No | F7: =Instructions!J14 -> N | G7: =Instructions!K14 -> Proofed | H7: =IF(ISBLANK(Instructions!L14),"",Instructions!L14) -> 45957 | I7: =IF(ISBLANK(Instructions!M14),"",Instructions!M14) -> Lily Harmon | J7: =IF(ISBLANK(Instructions!N14),"",Instructions!N14) -> 45957 | K7: =IF(ISBLANK(Instructions!O14),"",Instructions!O14) -> Lily Harmon | L7: =IF(ISBLANK(Instructions!P14),"",Instructions!P14) | M7: =Instructions!Q14 -> Added via SMSS
A8: =_xlfn.CONCAT(Instructions!C15,Instructions!D15,"D",TEXT(Instructions!B15,"YY"),TEXT(Instructions!B15,"MM"),"-",TEXT(Instructions!F15,"00")) -> LXND2509-22 | B8: {=_xlfn.CONCAT(Instructions!C15,Instructions!A15,"_",TEXT(Instructions!B15,"YYYYMMDD"),"_1_",INDEX(Table1[], MATCH(1,(Table1[Estuary]=Instructions!C15)*(Table1[SectionName]=Instructions!D15)*(Table1[StationNumber]=Instructions!E15)*(Instructions!B15>Table1[StartDate])*(Instructions!B15<Table1[EndDate]),0),1),"_1")} -> LXCOLL_20250903_1_0242_1 | C8: =Instructions!G15 -> M | D8: =Instructions!H15 -> 2 | E8: =Instructions!I15 -> No | F8: =Instructions!J15 -> N | G8: =Instructions!K15 -> Proofed | H8: =IF(ISBLANK(Instructions!L15),"",Instructions!L15) -> 45957 | I8: =IF(ISBLANK(Instructions!M15),"",Instructions!M15) -> Lily Harmon | J8: =IF(ISBLANK(Instructions!N15),"",Instructions!N15) -> 45957 | K8: =IF(ISBLANK(Instructions!O15),"",Instructions!O15) -> Lily Harmon | L8: =IF(ISBLANK(Instructions!P15),"",Instructions!P15) | M8: =Instructions!Q15 -> Added via SMSS
A9: =_xlfn.CONCAT(Instructions!C16,Instructions!D16,"D",TEXT(Instructions!B16,"YY"),TEXT(Instructions!B16,"MM"),"-",TEXT(Instructions!F16,"00")) -> LXND2509-23 | B9: {=_xlfn.CONCAT(Instructions!C16,Instructions!A16,"_",TEXT(Instructions!B16,"YYYYMMDD"),"_1_",INDEX(Table1[], MATCH(1,(Table1[Estuary]=Instructions!C16)*(Table1[SectionName]=Instructions!D16)*(Table1[StationNumber]=Instructions!E16)*(Instructions!B16>Table1[StartDate])*(Instructions!B16<Table1[EndDate]),0),1),"_1")} -> LXCOLL_20250903_1_0242_1 | C9: =Instructions!G16 -> Z | D9: =Instructions!H16 -> Z | E9: =Instructions!I16 -> No | F9: =Instructions!J16 -> Y | G9: =Instructions!K16 -> Proofed | H9: =IF(ISBLANK(Instructions!L16),"",Instructions!L16) -> 45957 | I9: =IF(ISBLANK(Instructions!M16),"",Instructions!M16) -> Lily Harmon | J9: =IF(ISBLANK(Instructions!N16),"",Instructions!N16) -> 45957 | K9: =IF(ISBLANK(Instructions!O16),"",Instructions!O16) -> Lily Harmon | L9: =IF(ISBLANK(Instructions!P16),"",Instructions!P16) | M9: =Instructions!Q16 -> Added via SMSS
A10: =_xlfn.CONCAT(Instructions!C17,Instructions!D17,"D",TEXT(Instructions!B17,"YY"),TEXT(Instructions!B17,"MM"),"-",TEXT(Instructions!F17,"00")) -> LXND2509-24 | B10: {=_xlfn.CONCAT(Instructions!C17,Instructions!A17,"_",TEXT(Instructions!B17,"YYYYMMDD"),"_1_",INDEX(Table1[], MATCH(1,(Table1[Estuary]=Instructions!C17)*(Table1[SectionName]=Instructions!D17)*(Table1[StationNumber]=Instructions!E17)*(Instructions!B17>Table1[StartDate])*(Instructions!B17<Table1[EndDate]),0),1),"_1")} -> LXCOLL_20250903_1_0242_1 | C10: =Instructions!G17 -> M | D10: =Instructions!H17 -> 2 | E10: =Instructions!I17 -> No | F10: =Instructions!J17 -> N | G10: =Instructions!K17 -> Proofed | H10: =IF(ISBLANK(Instructions!L17),"",Instructions!L17) -> 45957 | I10: =IF(ISBLANK(Instructions!M17),"",Instructions!M17) -> Lily Harmon | J10: =IF(ISBLANK(Instructions!N17),"",Instructions!N17) -> 45957 | K10: =IF(ISBLANK(Instructions!O17),"",Instructions!O17) -> Lily Harmon | L10: =IF(ISBLANK(Instructions!P17),"",Instructions!P17) | M10: =Instructions!Q17 -> Added via SMSS
A11: =_xlfn.CONCAT(Instructions!C18,Instructions!D18,"D",TEXT(Instructions!B18,"YY"),TEXT(Instructions!B18,"MM"),"-",TEXT(Instructions!F18,"00")) -> LXND2509-25 | B11: {=_xlfn.CONCAT(Instructions!C18,Instructions!A18,"_",TEXT(Instructions!B18,"YYYYMMDD"),"_1_",INDEX(Table1[], MATCH(1,(Table1[Estuary]=Instructions!C18)*(Table1[SectionName]=Instructions!D18)*(Table1[StationNumber]=Instructions!E18)*(Instructions!B18>Table1[StartDate])*(Instructions!B18<Table1[EndDate]),0),1),"_1")} -> LXCOLL_20250903_1_0242_1 | C11: =Instructions!G18 -> Z | D11: =Instructions!H18 -> Z | E11: =Instructions!I18 -> No | F11: =Instructions!J18 -> N | G11: =Instructions!K18 -> Proofed | H11: =IF(ISBLANK(Instructions!L18),"",Instructions!L18) -> 45957 | I11: =IF(ISBLANK(Instructions!M18),"",Instructions!M18) -> Lily Harmon | J11: =IF(ISBLANK(Instructions!N18),"",Instructions!N18) -> 45957 | K11: =IF(ISBLANK(Instructions!O18),"",Instructions!O18) -> Lily Harmon | L11: =IF(ISBLANK(Instructions!P18),"",Instructions!P18) -> Missing slide | M11: =Instructions!Q18 -> Added via SMSS
A12: =_xlfn.CONCAT(Instructions!C19,Instructions!D19,"D",TEXT(Instructions!B19,"YY"),TEXT(Instructions!B19,"MM"),"-",TEXT(Instructions!F19,"00")) -> LXND2509-26 | B12: {=_xlfn.CONCAT(Instructions!C19,Instructions!A19,"_",TEXT(Instructions!B19,"YYYYMMDD"),"_1_",INDEX(Table1[], MATCH(1,(Table1[Estuary]=Instructions!C19)*(Table1[SectionName]=Instructions!D19)*(Table1[StationNumber]=Instructions!E19)*(Instructions!B19>Table1[StartDate])*(Instructions!B19<Table1[EndDate]),0),1),"_1")} -> LXCOLL_20250903_1_0243_1 | C12: =Instructions!G19 -> M | D12: =Instructions!H19 -> 2 | E12: =Instructions!I19 -> No | F12: =Instructions!J19 -> N | G12: =Instructions!K19 -> Proofed | H12: =IF(ISBLANK(Instructions!L19),"",Instructions!L19) -> 45957 | I12: =IF(ISBLANK(Instructions!M19),"",Instructions!M19) -> Lily Harmon | J12: =IF(ISBLANK(Instructions!N19),"",Instructions!N19) -> 45957 | K12: =IF(ISBLANK(Instructions!O19),"",Instructions!O19) -> Lily Harmon | L12: =IF(ISBLANK(Instructions!P19),"",Instructions!P19) | M12: =Instructions!Q19 -> Added via SMSS
A13: =_xlfn.CONCAT(Instructions!C20,Instructions!D20,"D",TEXT(Instructions!B20,"YY"),TEXT(Instructions!B20,"MM"),"-",TEXT(Instructions!F20,"00")) -> LXND2509-27 | B13: {=_xlfn.CONCAT(Instructions!C20,Instructions!A20,"_",TEXT(Instructions!B20,"YYYYMMDD"),"_1_",INDEX(Table1[], MATCH(1,(Table1[Estuary]=Instructions!C20)*(Table1[SectionName]=Instructions!D20)*(Table1[StationNumber]=Instructions!E20)*(Instructions!B20>Table1[StartDate])*(Instructions!B20<Table1[EndDate]),0),1),"_1")} -> LXCOLL_20250903_1_0243_1 | C13: =Instructions!G20 -> M | D13: =Instructions!H20 -> 2 | E13: =Instructions!I20 -> No | F13: =Instructions!J20 -> N | G13: =Instructions!K20 -> Proofed | H13: =IF(ISBLANK(Instructions!L20),"",Instructions!L20) -> 45957 | I13: =IF(ISBLANK(Instructions!M20),"",Instructions!M20) -> Lily Harmon | J13: =IF(ISBLANK(Instructions!N20),"",Instructions!N20) -> 45957 | K13: =IF(ISBLANK(Instructions!O20),"",Instructions!O20) -> Lily Harmon | L13: =IF(ISBLANK(Instructions!P20),"",Instructions!P20) | M13: =Instructions!Q20 -> Added via SMSS
... A31: =_xlfn.CONCAT(Instructions!C38,Instructions!D38,"D",TEXT(Instructions!B38,"YY"),TEXT(Instructions!B38,"MM"),"-",TEXT(Instructions!F38,"00")) -> LXND2509-45 | B31: {=_xlfn.CONCAT(Instructions!C38,Instructions!A38,"_",TEXT(Instructions!B38,"YYYYMMDD"),"_1_",INDEX(Table1[], MATCH(1,(Table1[Estuary]=Instructions!C38)*(Table1[SectionName]=Instructions!D38)*(Table1[StationNumber]=Instructions!E38)*(Instructions!B38>Table1[StartDate])*(Instructions!B38<Table1[EndDate]),0),1),"_1")} -> LXCOLL_20250903_1_0244_1 | C31: =Instructions!G38 -> Z | D31: =Instructions!H38 -> 4 | E31: =Instructions!I38 -> No | F31: =Instructions!J38 -> N | G31: =Instructions!K38 -> Proofed | H31: =IF(ISBLANK(Instructions!L38),"",Instructions!L38) -> 45957 | I31: =IF(ISBLANK(Instructions!M38),"",Instructions!M38) -> Lily Harmon | J31: =IF(ISBLANK(Instructions!N38),"",Instructions!N38) -> 45957 | K31: =IF(ISBLANK(Instructions!O38),"",Instructions!O38) -> Lily Harmon | L31: =IF(ISBLANK(Instructions!P38),"",Instructions!P38) -> 0=imm | M31: =Instructions!Q38 -> Added via SMSS

Sheet FixedLocations
A1: FixedLocationID | B1: Estuary | C1: SectionName | D1: StationName | E1: StationNumber | F1: ParcelName | G1: ParcelArea | H1: CultchDensity | I1: LatitudeDec | J1: LongitudeDec | K1: Recruitment | L1: Survey | M1: Sediment | N1: Collections | O1: ShellBudget | P1: Dataloggers | Q1: Cage | R1: Wave | S1: StartDate | T1: EndDate | U1: DataStatus | V1: DateEntered | W1: EnteredBy | X1: DateProofed | Y1: ProofedBy | Z1: DateCompleted | AA1: CompletedBy | AB1: Comments | AC1: AdminNotes | AD1: StationNameNumber | AE1: EstuaryLongName | AF1: DateLastCultched
A2: T026 | B2: TB | C2: B | D2: TB B 27482_82461 34 | E2: 34 | F2: NULL | G2: NULL | H2: NULL | I2: 27.80391 | J2: -82.76939 | K2: N | L2: Y | M2: N | N2: Y | O2: N | P2: N | Q2: N | R2: N | S2: 45230 | T2: 45261 | U2: Completed | V2: 45268 | W2: EL | X2: NULL | Y2: NULL | Z2: NULL | AA2: NULL | AB2: 27482_82461 | AC2: NULL | AD2: TB-B-27482_82461-34 | AE2: Tampa Bay | AF2: NULL
A3: 0323 | B3: SS | C3: N | D3: SS-1 | E3: 1 | F3: NULL | G3: NULL | H3: NULL | I3: 29.435716 | J3: -83.264154 | K3: Y | L3: N | M3: N | N3: Y | O3: Y | P3: Y | Q3: N | R3: N | S3: 44562 | T3: 73050 | U3: Proofed | V3: NULL | W3: NULL | X3: NULL | Y3: NULL | Z3: NULL | AA3: NULL | AB3: NULL | AC3: old Station Name SS-N-1 added Collections ShellBudget Datalogger trip types | AD3: SS-N-1 | AE3: Suwannee Sound | AF3: NULL
A4: 0324 | B4: SS | C4: N | D4: SS-2 | E4: 2 | F4: NULL | G4: NULL | H4: NULL | I4: 29.429816 | J4: -83.235363 | K4: Y | L4: N | M4: N | N4: Y | O4: Y | P4: Y | Q4: N | R4: N | S4: 44562 | T4: 73050 | U4: Proofed | V4: NULL | W4: NULL | X4: NULL | Y4: NULL | Z4: NULL | AA4: NULL | AB4: NULL | AC4: old Station Name SS-N-2 added Collections ShellBudget Datalogger trip types | AD4: SS-N-2 | AE4: Suwannee Sound | AF4: NULL
A5: 0325 | B5: SS | C5: N | D5: SS-3 | E5: 3 | F5: NULL | G5: NULL | H5: NULL | I5: 29.416341 | J5: -83.240883 | K5: Y | L5: N | M5: N | N5: Y | O5: Y | P5: Y | Q5: N | R5: N | S5: 44562 | T5: 73050 | U5: Proofed | V5: NULL | W5: NULL | X5: NULL | Y5: NULL | Z5: NULL | AA5: NULL | AB5: NULL | AC5: old Station Name SS-N-3 added Collections ShellBudget Datalogger trip types | AD5: SS-N-3 | AE5: Suwannee Sound | AF5: NULL
A6: 0326 | B6: SS | C6: N | D6: SS-4 | E6: 4 | F6: NULL | G6: NULL | H6: NULL | I6: 29.409869 | J6: -83.215147 | K6: Y | L6: N | M6: N | N6: Y | O6: Y | P6: Y | Q6: N | R6: N | S6: 44562 | T6: 73050 | U6: Proofed | V6: NULL | W6: NULL | X6: NULL | Y6: NULL | Z6: NULL | AA6: NULL | AB6: NULL | AC6: old Station Name SS-N-4 added Collections ShellBudget Datalogger trip types | AD6: SS-N-4 | AE6: Suwannee Sound | AF6: NULL
A7: 0327 | B7: SS | C7: C | D7: SS-5 | E7: 5 | F7: NULL | G7: NULL | H7: NULL | I7: 29.363317 | J7: -83.182407 | K7: Y | L7: N | M7: N | N7: Y | O7: Y | P7: Y | Q7: N | R7: N | S7: 44562 | T7: 73050 | U7: Proofed | V7: NULL | W7: NULL | X7: NULL | Y7: NULL | Z7: NULL | AA7: NULL | AB7: NULL | AC7: old Station Name SS-C-5 added Collections ShellBudget Datalogger trip types | AD7: SS-C-5 | AE7: Suwannee Sound | AF7: NULL
A8: 0328 | B8: SS | C8: C | D8: SS-6 | E8: 6 | F8: NULL | G8: NULL | H8: NULL | I8: 29.296233 | J8: -83.18446 | K8: Y | L8: N | M8: N | N8: Y | O8: Y | P8: Y | Q8: N | R8: N | S8: 44562 | T8: 73050 | U8: Proofed | V8: NULL | W8: NULL | X8: NULL | Y8: NULL | Z8: NULL | AA8: NULL | AB8: NULL | AC8: old Station Name SS-C-6 added Collections ShellBudget Datalogger trip types | AD8: SS-C-6 | AE8: Suwannee Sound | AF8: NULL
A9: 0329 | B9: SS | C9: C | D9: SS-7 | E9: 7 | F9: NULL | G9: NULL | H9: NULL | I9: 29.260636 | J9: -83.109336 | K9: Y | L9: N | M9: N | N9: Y | O9: Y | P9: Y | Q9: N | R9: N | S9: 44562 | T9: 73050 | U9: Proofed | V9: NULL | W9: NULL | X9: NULL | Y9: NULL | Z9: NULL | AA9: NULL | AB9: NULL | AC9: old Station Name SS-C-7 added Collections ShellBudget Datalogger trip types | AD9: SS-C-7 | AE9: Suwannee Sound | AF9: NULL
A10: 0330 | B10: SS | C10: C | D10: SS-8 | E10: 8 | F10: NULL | G10: NULL | H10: NULL | I10: 29.236376 | J10: -83.07522 | K10: Y | L10: N | M10: N | N10: Y | O10: Y | P10: Y | Q10: N | R10: N | S10: 44562 | T10: 73050 | U10: Proofed | V10: NULL | W10: NULL | X10: NULL | Y10: NULL | Z10: NULL | AA10: NULL | AB10: NULL | AC10: old Station Name SS-C-8 added Collections ShellBudget Datalogger trip types | AD10: SS-C-8 | AE10: Suwannee Sound | AF10: NULL
A11: 0331 | B11: SS | C11: S | D11: SS-9 | E11: 9 | F11: NULL | G11: NULL | H11: NULL | I11: 29.194807 | J11: -83.083816 | K11: Y | L11: N | M11: N | N11: Y | O11: Y | P11: Y | Q11: N | R11: N | S11: 44562 | T11: 73050 | U11: Proofed | V11: NULL | W11: NULL | X11: NULL | Y11: NULL | Z11: NULL | AA11: NULL | AB11: NULL | AC11: old Station Name SS-S-9 added Collections ShellBudget Datalogger trip types | AD11: SS-S-9 | AE11: Suwannee Sound | AF11: NULL
A12: 0332 | B12: SS | C12: S | D12: SS-10 | E12: 10 | F12: NULL | G12: NULL | H12: NULL | I12: 29.136063 | J12: -83.055666 | K12: Y | L12: N | M12: N | N12: Y | O12: Y | P12: Y | Q12: N | R12: N | S12: 44562 | T12: 73050 | U12: Proofed | V12: NULL | W12: NULL | X12: NULL | Y12: NULL | Z12: NULL | AA12: NULL | AB12: NULL | AC12: old Station Name SS-S-10 added Collections ShellBudget Datalogger trip types | AD12: SS-S-10 | AE12: Suwannee Sound | AF12: NULL
A13: 0333 | B13: SS | C13: S | D13: SS-11 | E13: 11 | F13: NULL | G13: NULL | H13: NULL | I13: 29.154803 | J13: -82.995543 | K13: Y | L13: N | M13: N | N13: Y | O13: Y | P13: Y | Q13: N | R13: N | S13: 44562 | T13: 73050 | U13: Proofed | V13: NULL | W13: NULL | X13: NULL | Y13: NULL | Z13: NULL | AA13: NULL | AB13: NULL | AC13: old Station Name SS-S-11 added Collections ShellBudget Datalogger trip types | AD13: SS-S-11 | AE13: Suwannee Sound | AF13: NULL
A14: 334 | B14: SS | C14: S | D14: SS-12 | E14: 12 | F14: NULL | G14: NULL | H14: NULL | I14: 29.172815 | J14: -82.989328 | K14: Y | L14: N | M14: N | N14: Y | O14: Y | P14: Y | Q14: N | R14: N | S14: 44562 | T14: 73050 | U14: Proofed | V14: NULL | W14: NULL | X14: NULL | Y14: NULL | Z14: NULL | AA14: NULL | AB14: NULL | AC14: old Station Name SS-S-12 added Collections ShellBudget Datalogger trip types | AD14: SS-S-12 | AE14: Suwannee Sound | AF14: NULL
A15: 0618 | B15: SS | C15: C | D15: DI6 | E15: 6 | F15: Deer Island | G15: NULL | H15: NULL | I15: 29.23574 | J15: -83.072471 | K15: N | L15: Y | M15: N | N15: Y | O15: Y | P15: N | Q15: N | R15: N | S15: 45077 | T15: 73050 | U15: Proofed | V15: NULL | W15: NULL | X15: NULL | Y15: NULL | Z15: NULL | AA15: NULL | AB15: Harvest CR | AC15: removed space in Station Name | AD15: DI 6-6 | AE15: Suwannee Sound | AF15: NULL
A16: 0619 | B16: SS | C16: C | D16: TC1 | E16: 1 | F16: Trout Creek | G16: NULL | H16: NULL | I16: 29.2675 | J16: -83.0825 | K16: N | L16: Y | M16: N | N16: Y | O16: Y | P16: N | Q16: N | R16: N | S16: 45077 | T16: 73050 | U16: Proofed | V16: NULL | W16: NULL | X16: NULL | Y16: NULL | Z16: NULL | AA16: NULL | AB16: Harvest PD | AC16: removed space in Station Name | AD16: TC 1-1 | AE16: Suwannee Sound | AF16: NULL
A17: 0620 | B17: SS | C17: C | D17: TC2 | E17: 2 | F17: Trout Creek | G17: NULL | H17: NULL | I17: 29.259167 | J17: -83.075833 | K17: N | L17: Y | M17: N | N17: Y | O17: Y | P17: N | Q17: N | R17: N | S17: 45077 | T17: 73050 | U17: Proofed | V17: NULL | W17: NULL | X17: NULL | Y17: NULL | Z17: NULL | AA17: NULL | AB17: Harvest PD | AC17: removed space in Station Name | AD17: TC 2-2 | AE17: Suwannee Sound | AF17: NULL
A18: 0621 | B18: SS | C18: C | D18: TC3 | E18: 3 | F18: Trout Creek | G18: NULL | H18: NULL | I18: 29.264167 | J18: -83.080833 | K18: N | L18: Y | M18: N | N18: Y | O18: Y | P18: N | Q18: N | R18: N | S18: 45077 | T18: 73050 | U18: Proofed | V18: NULL | W18: NULL | X18: NULL | Y18: NULL | Z18: NULL | AA18: NULL | AB18: Harvest PD | AC18: removed space in Station Name | AD18: TC 3-3 | AE18: Suwannee Sound | AF18: NULL
A19: 0622 | B19: SS | C19: C | D19: TC4 | E19: 4 | F19: Trout Creek | G19: NULL | H19: NULL | I19: 29.265833 | J19: -83.080833 | K19: N | L19: Y | M19: N | N19: Y | O19: Y | P19: N | Q19: N | R19: N | S19: 45077 | T19: 73050 | U19: Proofed | V19: NULL | W19: NULL | X19: NULL | Y19: NULL | Z19: NULL | AA19: NULL | AB19: Harvest PD | AC19: removed space in Station Name | AD19: TC 4-4 | AE19: Suwannee Sound | AF19: NULL
A20: 0623 | B20: SS | C20: C | D20: TC5 | E20: 5 | F20: Trout Creek | G20: NULL | H20: NULL | I20: 29.260833 | J20: -83.069167 | K20: N | L20: Y | M20: N | N20: Y | O20: Y | P20: N | Q20: N | R20: N | S20: 45077 | T20: 73050 | U20: Proofed | V20: NULL | W20: NULL | X20: NULL | Y20: NULL | Z20: NULL | AA20: NULL | AB20: Harvest PD | AC20: removed space in Station Name | AD20: TC 5-5 | AE20: Suwannee Sound | AF20: NULL
A21: 0624 | B21: SS | C21: C | D21: TC6 | E21: 6 | F21: Trout Creek | G21: NULL | H21: NULL | I21: 29.260833 | J21: -83.074167 | K21: N | L21: Y | M21: N | N21: Y | O21: Y | P21: N | Q21: N | R21: N | S21: 45077 | T21: 73050 | U21: Proofed | V21: NULL | W21: NULL | X21: NULL | Y21: NULL | Z21: NULL | AA21: NULL | AB21: Harvest PD | AC21: removed space in Station Name | AD21: TC 6-6 | AE21: Suwannee Sound | AF21: NULL
A22: T027 | B22: TB | C22: L | D22: TB L 27382_82433 35 | E22: 35 | F22: NULL | G22: NULL | H22: NULL | I22: 27.63784 | J22: -82.72304 | K22: N | L22: Y | M22: N | N22: Y | O22: N | P22: N | Q22: N | R22: N | S22: 45291 | T22: 45383 | U22: Completed | V22: 45414 | W22: EL | X22: NULL | Y22: NULL | Z22: NULL | AA22: NULL | AB22: 27382_82433 | AC22: NULL | AD22: TB-L-27382_82433-35 | AE22: Tampa Bay | AF22: NULL
A23: T028 | B23: TB | C23: L | D23: TB L 27377_82434 36 | E23: 36 | F23: NULL | G23: NULL | H23: NULL | I23: 27.62993 | J23: -82.72372 | K23: N | L23: Y | M23: N | N23: Y | O23: N | P23: N | Q23: N | R23: N | S23: 45291 | T23: 45383 | U23: Completed | V23: 45414 | W23: EL | X23: NULL | Y23: NULL | Z23: NULL | AA23: NULL | AB23: 27377_82434 | AC23: NULL | AD23: TB-L-27377_82434-36 | AE23: Tampa Bay | AF23: NULL
A24: T029 | B24: TB | C24: L | D24: TB L 27373_82438 37 | E24: 37 | F24: NULL | G24: NULL | H24: NULL | I24: 27.62257 | J24: -82.73054 | K24: N | L24: Y | M24: N | N24: Y | O24: N | P24: N | Q24: N | R24: N | S24: 45291 | T24: 45383 | U24: Completed | V24: 45414 | W24: EL | X24: NULL | Y24: NULL | Z24: NULL | AA24: NULL | AB24: 27373_82438 | AC24: NULL | AD24: TB-L-27373_82438-37 | AE24: Tampa Bay | AF24: NULL
A25: T030 | B25: TB | C25: L | D25: TB L 27374_82438 38 | E25: 38 | F25: NULL | G25: NULL | H25: NULL | I25: 27.62486 | J25: -82.73138 | K25: N | L25: Y | M25: N | N25: Y | O25: N | P25: N | Q25: N | R25: N | S25: 45291 | T25: 45383 | U25: Completed | V25: 45414 | W25: EL | X25: NULL | Y25: NULL | Z25: NULL | AA25: NULL | AB25: 27374_82438 | AC25: NULL | AD25: TB-L-27374_82438-38 | AE25: Tampa Bay | AF25: NULL
A26: T031 | B26: TB | C26: L | D26: TB L 27371_82440 39 | E26: 39 | F26: NULL | G26: NULL | H26: NULL | I26: 27.61933 | J26: -82.73342 | K26: N | L26: Y | M26: N | N26: Y | O26: N | P26: N | Q26: N | R26: N | S26: 45291 | T26: 45383 | U26: Completed | V26: 45414 | W26: EL | X26: NULL | Y26: NULL | Z26: NULL | AA26: NULL | AB26: 27371_82440 | AC26: NULL | AD26: TB-L-27371_82440-39 | AE26: Tampa Bay | AF26: NULL
A27: T032 | B27: TB | C27: L | D27: TB L 27386_82428 40 | E27: 40 | F27: NULL | G27: NULL | H27: NULL | I27: 27.64392 | J27: -82.71442 | K27: N | L27: Y | M27: N | N27: Y | O27: N | P27: N | Q27: N | R27: N | S27: 45291 | T27: 45383 | U27: Completed | V27: 45414 | W27: EL | X27: NULL | Y27: NULL | Z27: NULL | AA27: NULL | AB27: 27386_82428 | AC27: NULL | AD27: TB-L-27386_82428-40 | AE27: Tampa Bay | AF27: NULL
A28: 0007 | B28: AB | C28: C | D28: Halfmoon | E28: 6 | F28: NULL | G28: NULL | H28: NULL | I28: 29.737666 | J28: -84.927316 | K28: Y | L28: Y | M28: Y | N28: Y | O28: N | P28: N | Q28: N | R28: N | S28: 42248 | T28: 73050 | U28: Proofed | V28: NULL | W28: NULL | X28: NULL | Y28: NULL | Z28: NULL | AA28: NULL | AB28: NULL | AC28: NULL | AD28: Halfmoon-6 | AE28: Apalachicola Bay | AF28: NULL
A29: 0011 | B29: AB | C29: C | D29: Lighthouse | E29: 7 | F29: NULL | G29: NULL | H29: NULL | I29: 29.709366 | J29: -84.9148 | K29: Y | L29: Y | M29: N | N29: Y | O29: N | P29: N | Q29: N | R29: N | S29: 42248 | T29: 73050 | U29: Proofed | V29: NULL | W29: NULL | X29: NULL | Y29: NULL | Z29: NULL | AA29: NULL | AB29: NULL | AC29: NULL | AD29: Lighthouse-7 | AE29: Apalachicola Bay | AF29: NULL
A30: 0016 | B30: AB | C30: C | D30: Normans | E30: 8 | F30: NULL | G30: NULL | H30: NULL | I30: 29.67795 | J30: -84.92735 | K30: Y | L30: Y | M30: N | N30: Y | O30: N | P30: N | Q30: N | R30: N | S30: 42248 | T30: 73050 | U30: Proofed | V30: NULL | W30: NULL | X30: NULL | Y30: NULL | Z30: NULL | AA30: NULL | AB30: NULL | AC30: NULL | AD30: Normans-8 | AE30: Apalachicola Bay | AF30: NULL
A31: 0019 | B31: AB | C31: C | D31: Hotel | E31: 9 | F31: NULL | G31: NULL | H31: NULL | I31: 29.671616 | J31: -84.90255 | K31: Y | L31: Y | M31: Y | N31: Y | O31: N | P31: N | Q31: N | R31: N | S31: 42248 | T31: 73050 | U31: Proofed | V31: NULL | W31: NULL | X31: NULL | Y31: NULL | Z31: NULL | AA31: NULL | AB31: NULL | AC31: NULL | AD31: Hotel-9 | AE31: Apalachicola Bay | AF31: NULL
A32: 0024 | B32: AB | C32: C | D32: East Lumps | E32: 10 | F32: NULL | G32: NULL | H32: NULL | I32: 29.713333 | J32: -84.900716 | K32: Y | L32: N | M32: N | N32: Y | O32: N | P32: N | Q32: N | R32: N | S32: 42005 | T32: 73050 | U32: Proofed | V32: NULL | W32: NULL | X32: NULL | Y32: NULL | Z32: NULL | AA32: NULL | AB32: NULL | AC32: NULL | AD32: East Lumps-10 | AE32: Apalachicola Bay | AF32: NULL
A33: 0090 | B33: AB | C33: E | D33: Cat Point | E33: 11 | F33: NULL | G33: NULL | H33: NULL | I33: 29.723766 | J33: -84.881333 | K33: Y | L33: Y | M33: N | N33: Y | O33: N | P33: N | Q33: N | R33: N | S33: 42248 | T33: 44075 | U33: Proofed | V33: NULL | W33: NULL | X33: NULL | Y33: NULL | Z33: NULL | AA33: NULL | AB33: NULL | AC33: NULL | AD33: Cat Point-11 | AE33: Apalachicola Bay | AF33: NULL
A34: 0091 | B34: AB | C34: E | D34: Cat Point | E34: 11 | F34: NULL | G34: NULL | H34: NULL | I34: 29.715716 | J34: -84.878466 | K34: Y | L34: Y | M34: N | N34: Y | O34: N | P34: N | Q34: N | R34: N | S34: 42248 | T34: 45382 | U34: Proofed | V34: NULL | W34: NULL | X34: NULL | Y34: NULL | Z34: NULL | AA34: NULL | AB34: NULL | AC34: NULL | AD34: Cat Point-11 | AE34: Apalachicola Bay | AF34: NULL
A35: 0096 | B35: AB | C35: E | D35: Easthole | E35: 12 | F35: NULL | G35: NULL | H35: NULL | I35: 29.676716 | J35: -84.8628 | K35: Y | L35: Y | M35: Y | N35: Y | O35: N | P35: N | Q35: N | R35: N | S35: 42005 | T35: 45382 | U35: Proofed | V35: NULL | W35: NULL | X35: NULL | Y35: NULL | Z35: NULL | AA35: NULL | AB35: NULL | AC35: NULL | AD35: Easthole-12 | AE35: Apalachicola Bay | AF35: NULL
A36: 0098 | B36: AB | C36: E | D36: Platform | E36: 13 | F36: NULL | G36: NULL | H36: NULL | I36: 29.702333 | J36: -84.836666 | K36: Y | L36: Y | M36: Y | N36: Y | O36: N | P36: N | Q36: N | R36: N | S36: 42005 | T36: 45382 | U36: Proofed | V36: NULL | W36: NULL | X36: NULL | Y36: NULL | Z36: NULL | AA36: NULL | AB36: NULL | AC36: NULL | AD36: Platform-13 | AE36: Apalachicola Bay | AF36: NULL
A37: 0100 | B37: AB | C37: E | D37: Porters | E37: 14 | F37: NULL | G37: NULL | H37: NULL | I37: 29.738716 | J37: -84.8366 | K37: Y | L37: Y | M37: N | N37: Y | O37: N | P37: N | Q37: N | R37: N | S37: 42005 | T37: 73050 | U37: Proofed | V37: NULL | W37: NULL | X37: NULL | Y37: NULL | Z37: NULL | AA37: NULL | AB37: NULL | AC37: NULL | AD37: Porters-14 | AE37: Apalachicola Bay | AF37: NULL
A38: 0102 | B38: AB | C38: E | D38: Bulkhead | E38: 15 | F38: NULL | G38: NULL | H38: NULL | I38: 29.68755 | J38: -84.880683 | K38: Y | L38: Y | M38: N | N38: Y | O38: N | P38: N | Q38: N | R38: N | S38: 42248 | T38: 73050 | U38: Proofed | V38: NULL | W38: NULL | X38: NULL | Y38: NULL | Z38: NULL | AA38: NULL | AB38: NULL | AC38: NULL | AD38: Bulkhead-15 | AE38: Apalachicola Bay | AF38: NULL
A39: 0155 | B39: AB | C39: W | D39: Paradise Flats | E39: 1 | F39: NULL | G39: NULL | H39: NULL | I39: 29.692916 | J39: -85.121583 | K39: Y | L39: Y | M39: N | N39: Y | O39: N | P39: N | Q39: N | R39: N | S39: 42248 | T39: 44104 | U39: Proofed | V39: NULL | W39: NULL | X39: NULL | Y39: NULL | Z39: NULL | AA39: NULL | AB39: NULL | AC39: NULL | AD39: Paradise Flats-1 | AE39: Apalachicola Bay | AF39: NULL
... A101: 0282 | B101: TB | C101: L | D101: TB Ft. Desoto | E101: 3 | F101: NULL | G101: NULL | H101: NULL | I101: 27.646066 | J101: -82.713233 | K101: Y | L101: Y | M101: N | N101: Y | O101: Y | P101: N | Q101: N | R101: N | S101: 38965 | T101: 73050 | U101: Proofed | V101: NULL | W101: NULL | X101: NULL | Y101: NULL | Z101: NULL | AA101: NULL | AB101: NULL | AC101: NULL | AD101: TB Ft. Desoto-3 | AE101: Tampa Bay | AF101: NULL
...
