Workbook

Sheet Instructions
A1: Instructions for use:
A2: 1. Determine the Estuary and Stations for which the data needs to be added. Confirm the stations are present in the FixedLocations Table.
A3: 2. Enter the four-letter data type (i.e. RCRT), the 2-letter estuary code, and the station number for the data in ColA-C.
A4: 3. Fill in the date and data columns as able. If no data is recorded, leave the cell blank. RecordNumber = per event record (i.e. "1" in most cases)
A5: 4. Enter your name and the date in the EnteredBy and DateEntered columns.
A6: 5. On the "Template" sheet, use the formulas in row 2 to fill down until all stations are represented. Make sure to fill formulas in all columns (A:X)
A8: DataType | B8: Date | C8: Estuary | D8: StationNumber | E8: QuadratNumber | F8: ShellHeightNumber | G8: ShellHeight | H8: DataStatus | I8: DateEntered | J8: EnteredBy | K8: DateProofed | L8: ProofedBy | M8: Comments
A9: SRVY | B9: 43732 | C9: TB | D9: 5 | E9: 01 | F9: 001 | G9: 53 | H9: Entered | I9: 45646 | J9: Erica Williams | M9: Added via SMSS
A10: SRVY | B10: 43732 | C10: TB | D10: 5 | E10: 01 | F10: 002 | G10: 27 | H10: Entered | I10: 45646 | J10: Erica Williams | M10: Added via SMSS
A11: SRVY | B11: 43732 | C11: TB | D11: 5 | E11: 01 | F11: 003 | G11: 20 | H11: Entered | I11: 45646 | J11: Erica Williams | M11: Added via SMSS
A12: SRVY | B12: 43732 | C12: TB | D12: 5 | E12: 01 | F12: 004 | G12: 17 | H12: Entered | I12: 45646 | J12: Erica Williams | M12: Added via SMSS
A13: SRVY | B13: 43732 | C13: TB | D13: 5 | E13: 01 | F13: 005 | G13: 14 | H13: Entered | I13: 45646 | J13: Erica Williams | M13: Added via SMSS
A14: SRVY | B14: 43732 | C14: TB | D14: 5 | E14: 01 | F14: 006 | G14: 36 | H14: Entered | I14: 45646 | J14: Erica Williams | M14: Added via SMSS
A15: SRVY | B15: 43732 | C15: TB | D15: 5 | E15: 01 | F15: 007 | G15: 30 | H15: Entered | I15: 45646 | J15: Erica Williams | M15: Added via SMSS
A16: SRVY | B16: 43732 | C16: TB | D16: 5 | E16: 01 | F16: 008 | G16: 32 | H16: Entered | I16: 45646 | J16: Erica Williams | M16: Added via SMSS
A17: SRVY | B17: 43732 | C17: TB | D17: 5 | E17: 01 | F17: 009 | G17: 51 | H17: Entered | I17: 45646 | J17: Erica Williams | M17: Added via SMSS
A18: SRVY | B18: 43732 | C18: TB | D18: 5 | E18: 01 | F18: 010 | G18: 8 | H18: Entered | I18: 45646 | J18: Erica Williams | M18: Added via SMSS
A19: SRVY | B19: 43732 | C19: TB | D19: 5 | E19: 01 | F19: 011 | G19: 10 | H19: Entered | I19: 45646 | J19: Erica Williams | M19: Added via SMSS
A20: SRVY | B20: 43732 | C20: TB | D20: 5 | E20: 01 | F20: 012 | G20: 67 | H20: Entered | I20: 45646 | J20: Erica Williams | M20: Added via SMSS
... A758: SRVY | B758: 43732 | C758: TB | D758: 5 | E758: 015 | F758: 050 | G758: 24 | H758: Entered | I758: 45646 | J758: Erica Williams | M758: Added via SMSS

Sheet Template
A1: ShellHeightID | B1: QuadratID | C1: ShellHeight | D1: DataStatus | E1: DateEntered | F1: EnteredBy | G1: DateProofed | H1: ProofedBy | I1: DateCompleted | J1: CompletedBy | K1: Comments | L1: AdminNotes
A2: {=_xlfn.CONCAT(Instructions!C9,Instructions!A9,"_",TEXT(Instructions!B9,"YYYYMMDD"),"_1_",INDEX(Table1[], MATCH(1,(Table1[Estuary]=Instructions!C9)*(Table1[StationNumber]=Instructions!D9)*(Instructions!B9>Table1[StartDate])*(Instructions!B9<Table1[EndDate]),0),1),"_1_",Instructions!E9,"_",Instructions!F9)} -> TBSRVY_20190924_1_0291_1_01_001 | B2: {=_xlfn.CONCAT(Instructions!C9,Instructions!A9,"_",TEXT(Instructions!B9,"YYYYMMDD"),"_1_",INDEX(Table1[], MATCH(1,(Table1[Estuary]=Instructions!C9)*(Table1[StationNumber]=Instructions!D9)*(Instructions!B9>Table1[StartDate])*(Instructions!B9<Table1[EndDate]),0),1),"_1_",Instructions!E9)} -> TBSRVY_20190924_1_0291_1_01 | C2: =Instructions!G9 -> 53 | D2: =IF(ISBLANK(Instructions!H9),"",Instructions!H9) -> Entered | E2: =IF(ISBLANK(Instructions!I9),"",Instructions!I9) -> 45646 | F2: =IF(ISBLANK(Instructions!J9),"",Instructions!J9) -> Erica Williams | G2: =IF(ISBLANK(Instructions!K9),"",Instructions!K9) | H2: =IF(ISBLANK(Instructions!L9),"",Instructions!L9) | I2: ="NULL" -> NULL | J2: ="NULL" -> NULL | K2: =Instructions!M9 -> Added via SMSS | L2: ="NULL" -> NULL
A3: {=_xlfn.CONCAT(Instructions!C10,Instructions!A10,"_",TEXT(Instructions!B10,"YYYYMMDD"),"_1_",INDEX(Table1[], MATCH(1,(Table1[Estuary]=Instructions!C10)*(Table1[StationNumber]=Instructions!D10)*(Instructions!B10>Table1[StartDate])*(Instructions!B10<Table1[EndDate]),0),1),"_1_",Instructions!E10,"_",Instructions!F10)} -> TBSRVY_20190924_1_0291_1_01_002 | B3: {=_xlfn.CONCAT(Instructions!C10,Instructions!A10,"_",TEXT(Instructions!B10,"YYYYMMDD"),"_1_",INDEX(Table1[], MATCH(1,(Table1[Estuary]=Instructions!C10)*(Table1[StationNumber]=Instructions!D10)*(Instructions!B10>Table1[StartDate])*(Instructions!B10<Table1[EndDate]),0),1),"_1_",Instructions!E10)} -> TBSRVY_20190924_1_0291_1_01 | C3: =Instructions!G10 -> 27 | D3: =IF(ISBLANK(Instructions!H10),"",Instructions!H10) -> Entered | E3: =IF(ISBLANK(Instructions!I10),"",Instructions!I10) -> 45646 | F3: =IF(ISBLANK(Instructions!J10),"",Instructions!J10) -> Erica Williams | G3: =IF(ISBLANK(Instructions!K10),"",Instructions!K10) | H3: =IF(ISBLANK(Instructions!L10),"",Instructions!L10) | I3: ="NULL" -> NULL | J3: ="NULL" -> NULL | K3: =Instructions!M10 -> Added via SMSS | L3: ="NULL" -> NULL
A4: {=_xlfn.CONCAT(Instructions!C11,Instructions!A11,"_",TEXT(Instructions!B11,"YYYYMMDD"),"_1_",INDEX(Table1[], MATCH(1,(Table1[Estuary]=Instructions!C11)*(Table1[StationNumber]=Instructions!D11)*(Instructions!B11>Table1[StartDate])*(Instructions!B11<Table1[EndDate]),0),1),"_1_",Instructions!E11,"_",Instructions!F11)} -> TBSRVY_20190924_1_0291_1_01_003 | B4: {=_xlfn.CONCAT(Instructions!C11,Instructions!A11,"_",TEXT(Instructions!B11,"YYYYMMDD"),"_1_",INDEX(Table1[], MATCH(1,(Table1[Estuary]=Instructions!C11)*(Table1[StationNumber]=Instructions!D11)*(Instructions!B11>Table1[StartDate])*(Instructions!B11<Table1[EndDate]),0),1),"_1_",Instructions!E11)} -> TBSRVY_20190924_1_0291_1_01 | C4: =Instructions!G11 -> 20 | D4: =IF(ISBLANK(Instructions!H11),"",Instructions!H11) -> Entered | E4: =IF(ISBLANK(Instructions!I11),"",Instructions!I11) -> 45646 | F4: =IF(ISBLANK(Instructions!J11),"",Instructions!J11) -> Erica Williams | G4: =IF(ISBLANK(Instructions!K11),"",Instructions!K11) | H4: =IF(ISBLANK(Instructions!L11),"",Instructions!L11) | I4: ="NULL" -> NULL | J4: ="NULL" -> NULL | K4: =Instructions!M11 -> Added via SMSS | L4: ="NULL" -> NULL
A5: {=_xlfn.CONCAT(Instructions!C12,Instructions!A12,"_",TEXT(Instructions!B12,"YYYYMMDD"),"_1_",INDEX(Table1[], MATCH(1,(Table1[Estuary]=Instructions!C12)*(Table1[StationNumber]=Instructions!D12)*(Instructions!B12>Table1[StartDate])*(Instructions!B12<Table1[EndDate]),0),1),"_1_",Instructions!E12,"_",Instructions!F12)} -> TBSRVY_20190924_1_0291_1_01_004 | B5: {=_xlfn.CONCAT(Instructions!C12,Instructions!A12,"_",TEXT(Instructions!B12,"YYYYMMDD"),"_1_",INDEX(Table1[], MATCH(1,(Table1[Estuary]=Instructions!C12)*(Table1[StationNumber]=Instructions!D12)*(Instructions!B12>Table1[StartDate])*(Instructions!B12<Table1[EndDate]),0),1),"_1_",Instructions!E12)} -> TBSRVY_20190924_1_0291_1_01 | C5: =Instructions!G12 -> 17 | D5: =IF(ISBLANK(Instructions!H12),"",Instructions!H12) -> Entered | E5: =IF(ISBLANK(Instructions!I12),"",Instructions!I12) -> 45646 | F5: =IF(ISBLANK(Instructions!J12),"",Instructions!J12) -> Erica Williams | G5: =IF(ISBLANK(Instructions!K12),"",Instructions!K12) | H5: =IF(ISBLANK(Instructions!L12),"",Instructions!L12) | I5: ="NULL" -> NULL | J5: ="NULL" -> NULL | K5: =Instructions!M12 -> Added via SMSS | L5: ="NULL" -> NULL
A6: {=_xlfn.CONCAT(Instructions!C13,Instructions!A13,"_",TEXT(Instructions!B13,"YYYYMMDD"),"_1_",INDEX(Table1[], MATCH(1,(Table1[Estuary]=Instructions!C13)*(Table1[StationNumber]=Instructions!D13)*(Instructions!B13>Table1[StartDate])*(Instructions!B13<Table1[EndDate]),0),1),"_1_",Instructions!E13,"_",Instructions!F13)} -> TBSRVY_20190924_1_0291_1_01_005 | B6: {=_xlfn.CONCAT(Instructions!C13,Instructions!A13,"_",TEXT(Instructions!B13,"YYYYMMDD"),"_1_",INDEX(Table1[], MATCH(1,(Table1[Estuary]=Instructions!C13)*(Table1[StationNumber]=Instructions!D13)*(Instructions!B13>Table1[StartDate])*(Instructions!B13<Table1[EndDate]),0),1),"_1_",Instructions!E13)} -> TBSRVY_20190924_1_0291_1_01 | C6: =Instructions!G13 -> 14 | D6: =IF(ISBLANK(Instructions!H13),"",Instructions!H13) -> Entered | E6: =IF(ISBLANK(Instructions!I13),"",Instructions!I13) -> 45646 | F6: =IF(ISBLANK(Instructions!J13),"",Instructions!J13) -> Erica Williams | G6: =IF(ISBLANK(Instructions!K13),"",Instructions!K13) | H6: =IF(ISBLANK(Instructions!L13),"",Instructions!L13) | I6: ="NULL" -> NULL | J6: ="NULL" -> NULL | K6: =Instructions!M13 -> Added via SMSS | L6: ="NULL" -> NULL
A7: {=_xlfn.CONCAT(Instructions!C14,Instructions!A14,"_",TEXT(Instructions!B14,"YYYYMMDD"),"_1_",INDEX(Table1[], MATCH(1,(Table1[Estuary]=Instructions!C14)*(Table1[StationNumber]=Instructions!D14)*(Instructions!B14>Table1[StartDate])*(Instructions!B14<Table1[EndDate]),0),1),"_1_",Instructions!E14,"_",Instructions!F14)} -> TBSRVY_20190924_1_0291_1_01_006 | B7: {=_xlfn.CONCAT(Instructions!C14,Instructions!A14,"_",TEXT(Instructions!B14,"YYYYMMDD"),"_1_",INDEX(Table1[], MATCH(1,(Table1[Estuary]=Instructions!C14)*(Table1[StationNumber]=Instructions!D14)*(Instructions!B14>Table1[StartDate])*(Instructions!B14<Table1[EndDate]),0),1),"_1_",Instructions!E14)} -> TBSRVY_20190924_1_0291_1_01 | C7: =Instructions!G14 -> 36 | D7: =IF(ISBLANK(Instructions!H14),"",Instructions!H14) -> Entered | E7: =IF(ISBLANK(Instructions!I14),"",Instructions!I14) -> 45646 | F7: =IF(ISBLANK(Instructions!J14),"",Instructions!J14) -> Erica Williams | G7: =IF(ISBLANK(Instructions!K14),"",Instructions!K14) | H7: =IF(ISBLANK(Instructions!L14),"",Instructions!L14) | I7: ="NULL" -> NULL | J7: ="NULL" -> NULL | K7: =Instructions!M14 -> Added via SMSS | L7: ="NULL" -> NULL
A8: {=_xlfn.CONCAT(Instructions!C15,Instructions!A15,"_",TEXT(Instructions!B15,"YYYYMMDD"),"_1_",INDEX(Table1[], MATCH(1,(Table1[Estuary]=Instructions!C15)*(Table1[StationNumber]=Instructions!D15)*(Instructions!B15>Table1[StartDate])*(Instructions!B15<Table1[EndDate]),0),1),"_1_",Instructions!E15,"_",Instructions!F15)} -> TBSRVY_20190924_1_0291_1_01_007 | B8: {=_xlfn.CONCAT(Instructions!C15,Instructions!A15,"_",TEXT(Instructions!B15,"YYYYMMDD"),"_1_",INDEX(Table1[], MATCH(1,(Table1[Estuary]=Instructions!C15)*(Table1[StationNumber]=Instructions!D15)*(Instructions!B15>Table1[StartDate])*(Instructions!B15<Table1[EndDate]),0),1),"_1_",Instructions!E15)} -> TBSRVY_20190924_1_0291_1_01 | C8: =Instructions!G15 -> 30 | D8: =IF(ISBLANK(Instructions!H15),"",Instructions!H15) -> Entered | E8: =IF(ISBLANK(Instructions!I15),"",Instructions!I15) -> 45646 | F8: =IF(ISBLANK(Instructions!J15),"",Instructions!J15) -> Erica Williams | G8: =IF(ISBLANK(Instructions!K15),"",Instructions!K15) | H8: =IF(ISBLANK(Instructions!L15),"",Instructions!L15) | I8: ="NULL" -> NULL | J8: ="NULL" -> NULL | K8: =Instructions!M15 -> Added via SMSS | L8: ="NULL" -> NULL
A9: {=_xlfn.CONCAT(Instructions!C16,Instructions!A16,"_",TEXT(Instructions!B16,"YYYYMMDD"),"_1_",INDEX(Table1[], MATCH(1,(Table1[Estuary]=Instructions!C16)*(Table1[StationNumber]=Instructions!D16)*(Instructions!B16>Table1[StartDate])*(Instructions!B16<Table1[EndDate]),0),1),"_1_",Instructions!E16,"_",Instructions!F16)} -> TBSRVY_20190924_1_0291_1_01_008 | B9: {=_xlfn.CONCAT(Instructions!C16,Instructions!A16,"_",TEXT(Instructions!B16,"YYYYMMDD"),"_1_",INDEX(Table1[], MATCH(1,(Table1[Estuary]=Instructions!C16)*(Table1[StationNumber]=Instructions!D16)*(Instructions!B16>Table1[StartDate])*(Instructions!B16<Table1[EndDate]),0),1),"_1_",Instructions!E16)} -> TBSRVY_20190924_1_0291_1_01 | C9: =Instructions!G16 -> 32 | D9: =IF(ISBLANK(Instructions!H16),"",Instructions!H16) -> Entered | E9: =IF(ISBLANK(Instructions!I16),"",Instructions!I16) -> 45646 | F9: =IF(ISBLANK(Instructions!J16),"",Instructions!J16) -> Erica Williams | G9: =IF(ISBLANK(Instructions!K16),"",Instructions!K16) | H9: =IF(ISBLANK(Instructions!L16),"",Instructions!L16) | I9: ="NULL" -> NULL | J9: ="NULL" -> NULL | K9: =Instructions!M16 -> Added via SMSS | L9: ="NULL" -> NULL
A10: {=_xlfn.CONCAT(Instructions!C17,Instructions!A17,"_",TEXT(Instructions!B17,"YYYYMMDD"),"_1_",INDEX(Table1[], MATCH(1,(Table1[Estuary]=Instructions!C17)*(Table1[StationNumber]=Instructions!D17)*(Instructions!B17>Table1[StartDate])*(Instructions!B17<Table1[EndDate]),0),1),"_1_",Instructions!E17,"_",Instructions!F17)} -> TBSRVY_20190924_1_0291_1_01_009 | B10: {=_xlfn.CONCAT(Instructions!C17,Instructions!A17,"_",TEXT(Instructions!B17,"YYYYMMDD"),"_1_",INDEX(Table1[], MATCH(1,(Table1[Estuary]=Instructions!C17)*(Table1[StationNumber]=Instructions!D17)*(Instructions!B17>Table1[StartDate])*(Instructions!B17<Table1[EndDate]),0),1),"_1_",Instructions!E17)} -> TBSRVY_20190924_1_0291_1_01 | C10: =Instructions!G17 -> 51 | D10: =IF(ISBLANK(Instructions!H17),"",Instructions!H17) -> Entered | E10: =IF(ISBLANK(Instructions!I17),"",Instructions!I17) -> 45646 | F10: =IF(ISBLANK(Instructions!J17),"",Instructions!J17) -> Erica Williams | G10: =IF(ISBLANK(Instructions!K17),"",Instructions!K17) | H10: =IF(ISBLANK(Instructions!L17),"",Instructions!L17) | I10: ="NULL" -> NULL | J10: ="NULL" -> NULL | K10: =Instructions!M17 -> Added via SMSS | L10: ="NULL" -> NULL
A11: {=_xlfn.CONCAT(Instructions!C18,Instructions!A18,"_",TEXT(Instructions!B18,"YYYYMMDD"),"_1_",INDEX(Table1[], MATCH(1,(Table1[Estuary]=Instructions!C18)*(Table1[StationNumber]=Instructions!D18)*(Instructions!B18>Table1[StartDate])*(Instructions!B18<Table1[EndDate]),0),1),"_1_",Instructions!E18,"_",Instructions!F18)} -> TBSRVY_20190924_1_0291_1_01_010 | B11: {=_xlfn.CONCAT(Instructions!C18,Instructions!A18,"_",TEXT(Instructions!B18,"YYYYMMDD"),"_1_",INDEX(Table1[], MATCH(1,(Table1[Estuary]=Instructions!C18)*(Table1[StationNumber]=Instructions!D18)*(Instructions!B18>Table1[StartDate])*(Instructions!B18<Table1[EndDate]),0),1),"_1_",Instructions!E18)} -> TBSRVY_20190924_1_0291_1_01 | C11: =Instructions!G18 -> 8 | D11: =IF(ISBLANK(Instructions!H18),"",Instructions!H18) -> Entered | E11: =IF(ISBLANK(Instructions!I18),"",Instructions!I18) -> 45646 | F11: =IF(ISBLANK(Instructions!J18),"",Instructions!J18) -> Erica Williams | G11: =IF(ISBLANK(Instructions!K18),"",Instructions!K18) | H11: =IF(ISBLANK(Instructions!L18),"",Instructions!L18) | I11: ="NULL" -> NULL | J11: ="NULL" -> NULL | K11: =Instructions!M18 -> Added via SMSS | L11: ="NULL" -> NULL
A12: {=_xlfn.CONCAT(Instructions!C19,Instructions!A19,"_",TEXT(Instructions!B19,"YYYYMMDD"),"_1_",INDEX(Table1[], MATCH(1,(Table1[Estuary]=Instructions!C19)*(Table1[StationNumber]=Instructions!D19)*(Instructions!B19>Table1[StartDate])*(Instructions!B19<Table1[EndDate]),0),1),"_1_",Instructions!E19,"_",Instructions!F19)} -> TBSRVY_20190924_1_0291_1_01_011 | B12: {=_xlfn.CONCAT(Instructions!C19,Instructions!A19,"_",TEXT(Instructions!B19,"YYYYMMDD"),"_1_",INDEX(Table1[], MATCH(1,(Table1[Estuary]=Instructions!C19)*(Table1[StationNumber]=Instructions!D19)*(Instructions!B19>Table1[StartDate])*(Instructions!B19<Table1[EndDate]),0),1),"_1_",Instructions!E19)} -> TBSRVY_20190924_1_0291_1_01 | C12: =Instructions!G19 -> 10 | D12: =IF(ISBLANK(Instructions!H19),"",Instructions!H19) -> Entered | E12: =IF(ISBLANK(Instructions!I19),"",Instructions!I19) -> 45646 | F12: =IF(ISBLANK(Instructions!J19),"",Instructions!J19) -> Erica Williams | G12: =IF(ISBLANK(Instructions!K19),"",Instructions!K19) | H12: =IF(ISBLANK(Instructions!L19),"",Instructions!L19) | I12: ="NULL" -> NULL | J12: ="NULL" -> NULL | K12: =Instructions!M19 -> Added via SMSS | L12: ="NULL" -> NULL
A13: {=_xlfn.CONCAT(Instructions!C20,Instructions!A20,"_",TEXT(Instructions!B20,"YYYYMMDD"),"_1_",INDEX(Table1[], MATCH(1,(Table1[Estuary]=Instructions!C20)*(Table1[StationNumber]=Instructions!D20)*(Instructions!B20>Table1[StartDate])*(Instructions!B20<Table1[EndDate]),0),1),"_1_",Instructions!E20,"_",Instructions!F20)} -> TBSRVY_20190924_1_0291_1_01_012 | B13: {=_xlfn.CONCAT(Instructions!C20,Instructions!A20,"_",TEXT(Instructions!B20,"YYYYMMDD"),"_1_",INDEX(Table1[], MATCH(1,(Table1[Estuary]=Instructions!C20)*(Table1[StationNumber]=Instructions!D20)*(Instructions!B20>Table1[StartDate])*(Instructions!B20<Table1[EndDate]),0),1),"_1_",Instructions!E20)} -> TBSRVY_20190924_1_0291_1_01 | C13: =Instructions!G20 -> 67 | D13: =IF(ISBLANK(Instructions!H20),"",Instructions!H20) -> Entered | E13: =IF(ISBLANK(Instructions!I20),"",Instructions!I20) -> 45646 | F13: =IF(ISBLANK(Instructions!J20),"",Instructions!J20) -> Erica Williams | G13: =IF(ISBLANK(Instructions!K20),"",Instructions!K20) | H13: =IF(ISBLANK(Instructions!L20),"",Instructions!L20) | I13: ="NULL" -> NULL | J13: ="NULL" -> NULL | K13: =Instructions!M20 -> Added via SMSS | L13: ="NULL" -> NULL
... A751: {=_xlfn.CONCAT(Instructions!C758,Instructions!A758,"_",TEXT(Instructions!B758,"YYYYMMDD"),"_1_",INDEX(Table1[], MATCH(1,(Table1[Estuary]=Instructions!C758)*(Table1[StationNumber]=Instructions!D758)*(Instructions!B758>Table1[StartDate])*(Instructions!B758<Table1[EndDate]),0),1),"_1_",Instructions!E758,"_",Instructions!F758)} -> TBSRVY_20190924_1_0291_1_015_050 | B751: {=_xlfn.CONCAT(Instructions!C758,Instructions!A758,"_",TEXT(Instructions!B758,"YYYYMMDD"),"_1_",INDEX(Table1[], MATCH(1,(Table1[Estuary]=Instructions!C758)*(Table1[StationNumber]=Instructions!D758)*(Instructions!B758>Table1[StartDate])*(Instructions!B758<Table1[EndDate]),0),1),"_1_",Instructions!E758)} -> TBSRVY_20190924_1_0291_1_015 | C751: =Instructions!G758 -> 24 | D751: =IF(ISBLANK(Instructions!H758),"",Instructions!H758) -> Entered | E751: =IF(ISBLANK(Instructions!I758),"",Instructions!I758) -> 45646 | F751: =IF(ISBLANK(Instructions!J758),"",Instructions!J758) -> Erica Williams | G751: =IF(ISBLANK(Instructions!K758),"",Instructions!K758) | H751: =IF(ISBLANK(Instructions!L758),"",Instructions!L758) | I751: ="NULL" -> NULL | J751: ="NULL" -> NULL | K751: =Instructions!M758 -> Added via SMSS | L751: ="NULL" -> NULL

Sheet FixedLocations
A1: FixedLocationID | B1: Estuary | C1: SectionName | D1: StationName | E1: StationNumber | F1: LatitudeDec | G1: LongitudeDec | H1: Recruitment | I1: Survey | J1: Sediment | K1: Collections | L1: ShellBudget | M1: Dataloggers | N1: Cage | O1: Wave | P1: StartDate | Q1: EndDate | R1: StationNameNumber | S1: EstuaryLongName
A2: 0003 | B2: AB | C2: C | D2: NFWF Hotel Bar | E2: 3 | F2: 29.6716 | G2: -84.90442 | H2: N | I2: N | J2: N | K2: N | L2: N | M2: N | N2: N | O2: N | P2: 42156 | Q2: 43830 | R2: NFWF Hotel Bar-3 | S2: Apalachicola Bay
A3: 0004 | B3: AB | C3: C | D3: NFWF Hotel Bar | E3: 4 | F3: 29.67162 | G3: -84.90363 | H3: N | I3: N | J3: N | K3: N | L3: N | M3: N | N3: N | O3: N | P3: 42156 | Q3: 43830 | R3: NFWF Hotel Bar-4 | S3: Apalachicola Bay
A4: 0005 | B4: AB | C4: C | D4: NFWF Hotel Bar | E4: 5 | F4: 29.67147 | G4: -84.90288 | H4: N | I4: N | J4: N | K4: N | L4: N | M4: N | N4: N | O4: N | P4: 42156 | Q4: 43830 | R4: NFWF Hotel Bar-5 | S4: Apalachicola Bay
A5: 0006 | B5: AB | C5: C | D5: Halfmoon | E5: 6 | F5: 29.73755 | G5: -84.923833 | H5: Y | I5: Y | J5: N | K5: N | L5: N | M5: N | N5: N | O5: N | P5: 42005 | Q5: 42258 | R5: Halfmoon-6 | S5: Apalachicola Bay
A6: 0007 | B6: AB | C6: C | D6: Halfmoon | E6: 6 | F6: 29.737666 | G6: -84.927316 | H6: Y | I6: Y | J6: Y | K6: Y | L6: N | M6: N | N6: N | O6: N | P6: 42248 | Q6: 73050 | R6: Halfmoon-6 | S6: Apalachicola Bay
A7: 0008 | B7: AB | C7: C | D7: Sediment Halfmoon | E7: 6 | F7: 29.73455 | G7: -84.92615 | H7: N | I7: N | J7: Y | K7: N | L7: N | M7: N | N7: N | O7: N | P7: 43101 | Q7: 44773 | R7: Sediment Halfmoon-6 | S7: Apalachicola Bay
A8: 0009 | B8: AB | C8: C | D8: SBM Halfmoon | E8: 6 | F8: 29.73687 | G8: -84.92697 | H8: N | I8: N | J8: N | K8: N | L8: Y | M8: N | N8: N | O8: N | P8: 43466 | Q8: 73050 | R8: SBM Halfmoon-6 | S8: Apalachicola Bay
A9: 0010 | B9: AB | C9: C | D9: Lighthouse | E9: 7 | F9: 29.708333 | G9: -84.921233 | H9: Y | I9: Y | J9: N | K9: N | L9: N | M9: N | N9: N | O9: N | P9: 42005 | Q9: 42258 | R9: Lighthouse-7 | S9: Apalachicola Bay
A10: 0011 | B10: AB | C10: C | D10: Lighthouse | E10: 7 | F10: 29.709366 | G10: -84.9148 | H10: Y | I10: Y | J10: N | K10: Y | L10: N | M10: N | N10: N | O10: N | P10: 42248 | Q10: 73050 | R10: Lighthouse-7 | S10: Apalachicola Bay
A11: 0012 | B11: AB | C11: C | D11: SBM Lighthouse | E11: 7 | F11: 29.71233 | G11: -84.91598 | H11: N | I11: N | J11: N | K11: N | L11: Y | M11: N | N11: N | O11: N | P11: 43466 | Q11: 44469 | R11: SBM Lighthouse-7 | S11: Apalachicola Bay
A12: 0013 | B12: AB | C12: C | D12: SBM Lighthouse | E12: 7 | F12: 29.71178 | G12: -84.91548 | H12: N | I12: N | J12: N | K12: N | L12: Y | M12: N | N12: N | O12: N | P12: 43466 | Q12: 44469 | R12: SBM Lighthouse-7 | S12: Apalachicola Bay
A13: 0014 | B13: AB | C13: C | D13: SBM Lighthouse | E13: 7 | F13: 29.71052 | G13: -84.91508 | H13: N | I13: N | J13: N | K13: N | L13: Y | M13: N | N13: N | O13: N | P13: 43466 | Q13: 44469 | R13: SBM Lighthouse-7 | S13: Apalachicola Bay
... A281: 0282 | B281: TB | C281: L | D281: TB Ft. Desoto | E281: 3 | F281: 27.646066 | G281: -82.713233 | H281: Y | I281: Y | J281: N | K281: Y | L281: Y | M281: N | N281: N | O281: N | P281: 38965 | Q281: 73050 | R281: TB Ft. Desoto-3 | S281: Tampa Bay
A282: 0283 | B282: TB | C282: L | D282: FCMP LE-D-Seawall | E282: NULL | F282: 27.723316 | G282: -82.737916 | H282: Y | I282: Y | J282: N | K282: Y | L282: N | M282: N | N282: N | O282: N | P282: 39722 | Q282: 40179 | R282: FCMP LE-D-Seawall | S282: Tampa Bay
A283: 0284 | B283: TB | C283: L | D283: FCMP LE-D-Mangrove | E283: NULL | F283: 27.7381 | G283: -82.693916 | H283: Y | I283: Y | J283: N | K283: Y | L283: N | M283: N | N283: N | O283: N | P283: 39722 | Q283: 40179 | R283: FCMP LE-D-Mangrove | S283: Tampa Bay
A284: 0285 | B284: TB | C284: L | D284: FCMP LE-D-Reef | E284: NULL | F284: 27.737283 | G284: -82.693466 | H284: Y | I284: Y | J284: N | K284: Y | L284: N | M284: N | N284: N | O284: N | P284: 39722 | Q284: 40179 | R284: FCMP LE-D-Reef | S284: Tampa Bay
A285: 0286 | B285: TB | C285: L | D285: FCMP LE-D-Rest | E285: NULL | F285: 27.723316 | G285: -82.737916 | H285: Y | I285: Y | J285: N | K285: Y | L285: N | M285: N | N285: N | O285: N | P285: 39722 | Q285: 40179 | R285: FCMP LE-D-Rest | S285: Tampa Bay
A286: 0287 | B286: TB | C286: L | D286: FCMP LE-S-Seawall | E286: NULL | F286: 27.685983 | G286: -82.71885 | H286: Y | I286: Y | J286: N | K286: Y | L286: N | M286: N | N286: N | O286: N | P286: 39722 | Q286: 40179 | R286: FCMP LE-S-Seawall | S286: Tampa Bay
A287: 0288 | B287: TB | C287: L | D287: FCMP LE-S-Mangrove | E287: NULL | F287: 27.685333 | G287: -82.71735 | H287: Y | I287: Y | J287: N | K287: Y | L287: N | M287: N | N287: N | O287: N | P287: 39722 | Q287: 40179 | R287: FCMP LE-S-Mangrove | S287: Tampa Bay
A288: 0289 | B288: TB | C288: L | D288: FCMP LE-S-Reef | E288: NULL | F288: 27.685516 | G288: -82.716966 | H288: Y | I288: Y | J288: N | K288: Y | L288: N | M288: N | N288: N | O288: N | P288: 39722 | Q288: 40179 | R288: FCMP LE-S-Reef | S288: Tampa Bay
A289: 0290 | B289: TB | C289: L | D289: FCMP LE-S-Rest | E289: NULL | F289: 27.685516 | G289: -82.716966 | H289: Y | I289: Y | J289: N | K289: Y | L289: N | M289: N | N289: N | O289: N | P289: 39722 | Q289: 40179 | R289: FCMP LE-S-Rest | S289: Tampa Bay
A290: 0291 | B290: TB | C290: M | D290: TB Weedon | E290: 5 | F290: 27.84225 | G290: -82.609583 | H290: Y | I290: Y | J290: Y | K290: Y | L290: N | M290: N | N290: N | O290: Y | P290: 42370 | Q290: 73050 | R290: TB Weedon-5 | S290: Tampa Bay
A291: 0292 | B291: TB | C291: M | D291: FCMP ME-D-Seawall | E291: NULL | F291: 27.799716 | G291: -82.633416 | H291: Y | I291: Y | J291: N | K291: Y | L291: N | M291: N | N291: N | O291: N | P291: 39722 | Q291: 40179 | R291: FCMP ME-D-Seawall | S291: Tampa Bay
A292: 0293 | B292: TB | C292: M | D292: FCMP ME-D-Mangrove | E292: NULL | F292: 27.795783 | G292: -82.630916 | H292: Y | I292: Y | J292: N | K292: Y | L292: N | M292: N | N292: N | O292: N | P292: 39722 | Q292: 40179 | R292: FCMP ME-D-Mangrove | S292: Tampa Bay
A293: 0294 | B293: TB | C293: M | D293: FCMP ME-D-Reef | E293: NULL | F293: 27.7959 | G293: -82.631316 | H293: Y | I293: Y | J293: N | K293: Y | L293: N | M293: N | N293: N | O293: N | P293: 39722 | Q293: 40179 | R293: FCMP ME-D-Reef | S293: Tampa Bay
A294: 0295 | B294: TB | C294: M | D294: FCMP ME-D-Rest | E294: NULL | F294: 27.799716 | G294: -82.633416 | H294: Y | I294: Y | J294: N | K294: Y | L294: N | M294: N | N294: N | O294: N | P294: 39722 | Q294: 40179 | R294: FCMP ME-D-Rest | S294: Tampa Bay
A295: 0296 | B295: TB | C295: M | D295: FCMP ME-S-Seawall | E295: NULL | F295: 27.806316 | G295: -82.411533 | H295: Y | I295: Y | J295: N | K295: Y | L295: N | M295: N | N295: N | O295: N | P295: 39722 | Q295: 40179 | R295: FCMP ME-S-Seawall | S295: Tampa Bay
A296: 0297 | B296: TB | C296: M | D296: FCMP ME-S-Mangrove | E296: NULL | F296: 27.817216 | G296: -82.39825 | H296: Y | I296: Y | J296: N | K296: Y | L296: N | M296: N | N296: N | O296: N | P296: 39722 | Q296: 40179 | R296: FCMP ME-S-Mangrove | S296: Tampa Bay
A297: 0298 | B297: TB | C297: M | D297: FCMP ME-S-Reef | E297: NULL | F297: 27.817483 | G297: -82.3977 | H297: Y | I297: Y | J297: N | K297: Y | L297: N | M297: N | N297: N | O297: N | P297: 39722 | Q297: 40179 | R297: FCMP ME-S-Reef | S297: Tampa Bay
A298: 0299 | B298: TB | C298: M | D298: FCMP ME-S-Rest | E298: NULL | F298: 27.814933 | G298: -82.402033 | H298: Y | I298: Y | J298: N | K298: Y | L298: N | M298: N | N298: N | O298: N | P298: 39722 | Q298: 40179 | R298: FCMP ME-S-Rest | S298: Tampa Bay
A299: 0300 | B299: TB | C299: U | D299: FCMP UE-D-Seawall | E299: NULL | F299: 27.895083 | G299: -82.487166 | H299: Y | I299: Y | J299: N | K299: Y | L299: N | M299: N | N299: N | O299: N | P299: 39722 | Q299: 40179 | R299: FCMP UE-D-Seawall | S299: Tampa Bay
A300: 0301 | B300: TB | C300: U | D300: FCMP UE-D-Mangrove | E300: NULL | F300: 27.8974 | G300: -82.4342 | H300: Y | I300: Y | J300: N | K300: Y | L300: N | M300: N | N300: N | O300: N | P300: 39722 | Q300: 40179 | R300: FCMP UE-D-Mangrove | S300: Tampa Bay
A301: 0302 | B301: TB | C301: U | D301: FCMP UE-D-Reef | E301: NULL | F301: 27.8974 | G301: -82.4342 | H301: Y | I301: Y | J301: N | K301: Y | L301: N | M301: N | N301: N | O301: N | P301: 39722 | Q301: 40179 | R301: FCMP UE-D-Reef | S301: Tampa Bay
A302: 0303 | B302: TB | C302: U | D302: FCMP UE-D-Rest | E302: NULL | F302: 27.895083 | G302: -82.487166 | H302: Y | I302: Y | J302: N | K302: Y | L302: N | M302: N | N302: N | O302: N | P302: 39722 | Q302: 40179 | R302: FCMP UE-D-Rest | S302: Tampa Bay
... A306: 0307 | B306: TB | C306: U | D306: FCMP UE-S-Rest | E306: NULL | F306: 27.89255 | G306: -82.541066 | H306: Y | I306: Y | J306: N | K306: Y | L306: N | M306: N | N306: N | O306: N | P306: 39722 | Q306: 40179 | R306: FCMP UE-S-Rest | S306: Tampa Bay
A307: 0308 | B307: AB | C307: W | D307: Dry Bar North | E307: 3 | F307: 29.68057 | G307: -85.05805 | H307: Y | I307: Y | J307: N | K307: Y | L307: N | M307: N | N307: N | O307: N | P307: 44480 | Q307: 73050 | R307: Dry Bar North-3 | S307: Apalachicola Bay
A308: 0309 | B308: AB | C308: C | D308: SBM Lighthouse | E308: 7 | F308: 29.71163 | G308: -84.91538 | H308: N | I308: N | J308: N | K308: N | L308: Y | M308: N | N308: N | O308: N | P308: 44470 | Q308: 73050 | R308: SBM Lighthouse-Restoration | S308: Apalachicola Bay
A309: 0310 | B309: AB | C309: C | D309: SBM East Lumps | E309: 10 | F309: 29.71267 | G309: -84.89977 | H309: N | I309: N | J309: N | K309: N | L309: Y | M309: N | N309: N | O309: N | P309: 44470 | Q309: 73050 | R309: SBM EastLumps-Restoration | S309: Apalachicola Bay
A310: 0311 | B310: AB | C310: E | D310: SBM Cat Point | E310: 11 | F310: 29.71162 | G310: -84.87802 | H310: N | I310: N | J310: N | K310: N | L310: Y | M310: N | N310: N | O310: N | P310: 44470 | Q310: 73050 | R310: SBM Cat Point-Restoration | S310: Apalachicola Bay
...
